2025-07-02 22:19:23,069 INFO Run parameters: {'model': 'checkpoints/checkpoint_ep1500.pt', 'models': None, 'n': 100, 'replay_dir': 'replays', 'opponent': 'random'}
2025-07-02 22:19:36,042 ERROR [TIMEOUT] player_0 last_request not updated
2025-07-02 22:19:48,210 ERROR [TIMEOUT] player_1 last_request not updated
2025-07-02 22:19:48,238 ERROR Task exception was never retrieved
future: <Task finished name='Task-44' coro=<PSClient._handle_message() done, defined at C:\Users\こう\Documents\GitHub\Maple\Maple\copy_of_poke-env\poke_env\ps_client\ps_client.py:128> exception=RuntimeError('Battle request not updated')>
Traceback (most recent call last):
  File "C:\Users\こう\.pyenv\pyenv-win\versions\3.12.9\Lib\asyncio\tasks.py", line 520, in wait_for
    return await fut
           ^^^^^^^^^
  File "C:\Users\こう\Documents\GitHub\Maple\Maple\src\env\env_player.py", line 107, in _wait_update
    await asyncio.sleep(0.1)
  File "C:\Users\こう\.pyenv\pyenv-win\versions\3.12.9\Lib\asyncio\tasks.py", line 665, in sleep
    return await future
           ^^^^^^^^^^^^
asyncio.exceptions.CancelledError

The above exception was the direct cause of the following exception:

Traceback (most recent call last):
  File "C:\Users\こう\Documents\GitHub\Maple\Maple\src\env\env_player.py", line 110, in _handle_battle_request
    await asyncio.wait_for(_wait_update(), timeout=self._env.timeout)
  File "C:\Users\こう\.pyenv\pyenv-win\versions\3.12.9\Lib\asyncio\tasks.py", line 519, in wait_for
    async with timeouts.timeout(timeout):
               ^^^^^^^^^^^^^^^^^^^^^^^^^
  File "C:\Users\こう\.pyenv\pyenv-win\versions\3.12.9\Lib\asyncio\timeouts.py", line 115, in __aexit__
    raise TimeoutError from exc_val
TimeoutError

The above exception was the direct cause of the following exception:

Traceback (most recent call last):
  File "C:\Users\こう\Documents\GitHub\Maple\Maple\copy_of_poke-env\poke_env\ps_client\ps_client.py", line 197, in _handle_message
    raise exception
  File "C:\Users\こう\Documents\GitHub\Maple\Maple\copy_of_poke-env\poke_env\ps_client\ps_client.py", line 142, in _handle_message
    await self._handle_battle_message(split_messages)  # type: ignore
    ^^^^^^^^^^^^^^^^^^^^^^^^^^^^^^^^^^^^^^^^^^^^^^^^^
  File "C:\Users\こう\Documents\GitHub\Maple\Maple\copy_of_poke-env\poke_env\player\player.py", line 399, in _handle_battle_message
    await self._handle_battle_request(battle)
  File "C:\Users\こう\Documents\GitHub\Maple\Maple\src\env\env_player.py", line 115, in _handle_battle_request
    raise RuntimeError("Battle request not updated") from exc
RuntimeError: Battle request not updated
2025-07-02 22:19:48,239 ERROR Task exception was never retrieved
future: <Task finished name='Task-49' coro=<PSClient._handle_message() done, defined at C:\Users\こう\Documents\GitHub\Maple\Maple\copy_of_poke-env\poke_env\ps_client\ps_client.py:128> exception=RuntimeError('Battle request not updated')>
Traceback (most recent call last):
  File "C:\Users\こう\.pyenv\pyenv-win\versions\3.12.9\Lib\asyncio\tasks.py", line 520, in wait_for
    return await fut
           ^^^^^^^^^
  File "C:\Users\こう\Documents\GitHub\Maple\Maple\src\env\env_player.py", line 107, in _wait_update
    await asyncio.sleep(0.1)
  File "C:\Users\こう\.pyenv\pyenv-win\versions\3.12.9\Lib\asyncio\tasks.py", line 665, in sleep
    return await future
           ^^^^^^^^^^^^
asyncio.exceptions.CancelledError

The above exception was the direct cause of the following exception:

Traceback (most recent call last):
  File "C:\Users\こう\Documents\GitHub\Maple\Maple\src\env\env_player.py", line 110, in _handle_battle_request
    await asyncio.wait_for(_wait_update(), timeout=self._env.timeout)
  File "C:\Users\こう\.pyenv\pyenv-win\versions\3.12.9\Lib\asyncio\tasks.py", line 519, in wait_for
    async with timeouts.timeout(timeout):
               ^^^^^^^^^^^^^^^^^^^^^^^^^
  File "C:\Users\こう\.pyenv\pyenv-win\versions\3.12.9\Lib\asyncio\timeouts.py", line 115, in __aexit__
    raise TimeoutError from exc_val
TimeoutError

The above exception was the direct cause of the following exception:

Traceback (most recent call last):
  File "C:\Users\こう\Documents\GitHub\Maple\Maple\copy_of_poke-env\poke_env\ps_client\ps_client.py", line 197, in _handle_message
    raise exception
  File "C:\Users\こう\Documents\GitHub\Maple\Maple\copy_of_poke-env\poke_env\ps_client\ps_client.py", line 142, in _handle_message
    await self._handle_battle_message(split_messages)  # type: ignore
    ^^^^^^^^^^^^^^^^^^^^^^^^^^^^^^^^^^^^^^^^^^^^^^^^^
  File "C:\Users\こう\Documents\GitHub\Maple\Maple\copy_of_poke-env\poke_env\player\player.py", line 399, in _handle_battle_message
    await self._handle_battle_request(battle)
  File "C:\Users\こう\Documents\GitHub\Maple\Maple\src\env\env_player.py", line 115, in _handle_battle_request
    raise RuntimeError("Battle request not updated") from exc
RuntimeError: Battle request not updated
