2025-06-26 16:48:48,010 WARNING player_0 selected disabled action 0; fallback to 8
2025-06-26 16:48:48,011 WARNING player_0 selected disabled action 3; fallback to 0
2025-06-26 16:48:48,011 WARNING player_0 selected disabled action 1; fallback to 9
2025-06-26 16:48:48,028 WARNING player_1 selected disabled action 8; fallback to 3
2025-06-26 16:48:48,029 WARNING player_1 selected disabled action 5; fallback to 8
2025-06-26 16:48:48,029 WARNING player_1 selected disabled action 6; fallback to 9
2025-06-26 16:48:48,029 WARNING player_1 selected disabled action 3; fallback to 0
2025-06-26 16:48:48,604 WARNING player_0 selected disabled action 0; fallback to 3
2025-06-26 16:48:48,629 WARNING player_1 selected disabled action 0; fallback to 9
2025-06-26 16:48:52,022 WARNING player_0 selected disabled action 2; fallback to 8
2025-06-26 16:48:52,195 WARNING player_1 selected disabled action 1; fallback to 0
2025-06-26 16:48:52,513 ERROR [TIMEOUT] player_0 action queue empty=True waiting=False trying_again=False
2025-06-26 16:48:52,709 ERROR [TIMEOUT] player_1 action queue empty=True waiting=False trying_again=False
2025-06-26 16:48:52,711 ERROR [TIMEOUT] race_get queue=0 events=[False, False] exc=
2025-06-26 16:48:52,711 ERROR [TIMEOUT] race_get queue=0 events=[False, False] exc=
2025-06-26 16:48:53,034 ERROR [TIMEOUT] race_get queue=0 events=[False, False] exc=
2025-06-26 16:48:53,072 WARNING player_1 selected disabled action 3; fallback to 0
2025-06-26 16:48:53,799 ERROR Task exception was never retrieved
future: <Task finished name='Task-470' coro=<PSClient._handle_message() done, defined at /Users/takagikouichi/Documents/GitHub/Maple/copy_of_poke-env/poke_env/ps_client/ps_client.py:128> exception=TimeoutError()>
Traceback (most recent call last):
  File "/Users/takagikouichi/.pyenv/versions/3.12.9/lib/python3.12/asyncio/tasks.py", line 520, in wait_for
    return await fut
           ^^^^^^^^^
  File "/Users/takagikouichi/.pyenv/versions/3.12.9/lib/python3.12/asyncio/queues.py", line 158, in get
    await getter
asyncio.exceptions.CancelledError

The above exception was the direct cause of the following exception:

Traceback (most recent call last):
  File "/Users/takagikouichi/Documents/GitHub/Maple/copy_of_poke-env/poke_env/ps_client/ps_client.py", line 197, in _handle_message
    raise exception
  File "/Users/takagikouichi/Documents/GitHub/Maple/copy_of_poke-env/poke_env/ps_client/ps_client.py", line 142, in _handle_message
    await self._handle_battle_message(split_messages)  # type: ignore
    ^^^^^^^^^^^^^^^^^^^^^^^^^^^^^^^^^^^^^^^^^^^^^^^^^
  File "/Users/takagikouichi/Documents/GitHub/Maple/copy_of_poke-env/poke_env/player/player.py", line 399, in _handle_battle_message
    await self._handle_battle_request(battle)
  File "/Users/takagikouichi/Documents/GitHub/Maple/src/env/env_player.py", line 154, in _handle_battle_request
    choice = await choice
             ^^^^^^^^^^^^
  File "/Users/takagikouichi/Documents/GitHub/Maple/src/env/env_player.py", line 39, in choose_move
    action_data = await asyncio.wait_for(
                  ^^^^^^^^^^^^^^^^^^^^^^^
  File "/Users/takagikouichi/.pyenv/versions/3.12.9/lib/python3.12/asyncio/tasks.py", line 519, in wait_for
    async with timeouts.timeout(timeout):
               ^^^^^^^^^^^^^^^^^^^^^^^^^
  File "/Users/takagikouichi/.pyenv/versions/3.12.9/lib/python3.12/asyncio/timeouts.py", line 115, in __aexit__
    raise TimeoutError from exc_val
TimeoutError
2025-06-26 16:48:53,800 ERROR Task exception was never retrieved
future: <Task finished name='Task-1078' coro=<PSClient._handle_message() done, defined at /Users/takagikouichi/Documents/GitHub/Maple/copy_of_poke-env/poke_env/ps_client/ps_client.py:128> exception=TimeoutError()>
Traceback (most recent call last):
  File "/Users/takagikouichi/.pyenv/versions/3.12.9/lib/python3.12/asyncio/tasks.py", line 520, in wait_for
    return await fut
           ^^^^^^^^^
  File "/Users/takagikouichi/.pyenv/versions/3.12.9/lib/python3.12/asyncio/queues.py", line 158, in get
    await getter
asyncio.exceptions.CancelledError

The above exception was the direct cause of the following exception:

Traceback (most recent call last):
  File "/Users/takagikouichi/Documents/GitHub/Maple/copy_of_poke-env/poke_env/ps_client/ps_client.py", line 197, in _handle_message
    raise exception
  File "/Users/takagikouichi/Documents/GitHub/Maple/copy_of_poke-env/poke_env/ps_client/ps_client.py", line 142, in _handle_message
    await self._handle_battle_message(split_messages)  # type: ignore
    ^^^^^^^^^^^^^^^^^^^^^^^^^^^^^^^^^^^^^^^^^^^^^^^^^
  File "/Users/takagikouichi/Documents/GitHub/Maple/copy_of_poke-env/poke_env/player/player.py", line 399, in _handle_battle_message
    await self._handle_battle_request(battle)
  File "/Users/takagikouichi/Documents/GitHub/Maple/src/env/env_player.py", line 154, in _handle_battle_request
    choice = await choice
             ^^^^^^^^^^^^
  File "/Users/takagikouichi/Documents/GitHub/Maple/src/env/env_player.py", line 39, in choose_move
    action_data = await asyncio.wait_for(
                  ^^^^^^^^^^^^^^^^^^^^^^^
  File "/Users/takagikouichi/.pyenv/versions/3.12.9/lib/python3.12/asyncio/tasks.py", line 519, in wait_for
    async with timeouts.timeout(timeout):
               ^^^^^^^^^^^^^^^^^^^^^^^^^
  File "/Users/takagikouichi/.pyenv/versions/3.12.9/lib/python3.12/asyncio/timeouts.py", line 115, in __aexit__
    raise TimeoutError from exc_val
TimeoutError
2025-06-26 16:48:53,935 WARNING player_1 selected disabled action 1; fallback to 0
